Internal Server Error: /selvoc/wordbook/home/repeated_game/
Traceback (most recent call last):
  File "/Users/kei./anaconda3/lib/python3.6/site-packages/django/core/handlers/exception.py", line 34, in inner
    response = get_response(request)
  File "/Users/kei./anaconda3/lib/python3.6/site-packages/django/core/handlers/base.py", line 126, in _get_response
    response = self.process_exception_by_middleware(e, request)
  File "/Users/kei./anaconda3/lib/python3.6/site-packages/django/core/handlers/base.py", line 124, in _get_response
    response = wrapped_callback(request, *callback_args, **callback_kwargs)
  File "/Users/kei./anaconda3/lib/python3.6/contextlib.py", line 52, in inner
    return func(*args, **kwds)
  File "/Users/kei./anaconda3/lib/python3.6/site-packages/django/views/generic/base.py", line 68, in view
    return self.dispatch(request, *args, **kwargs)
  File "/Users/kei./Desktop/Django/wordbook/wordbook/views.py", line 194, in dispatch
    return super(RepeatedGameView, self).dispatch(request, *args, **kwargs)
  File "/Users/kei./anaconda3/lib/python3.6/site-packages/django/contrib/auth/mixins.py", line 52, in dispatch
    return super().dispatch(request, *args, **kwargs)
  File "/Users/kei./anaconda3/lib/python3.6/site-packages/django/views/generic/base.py", line 88, in dispatch
    return handler(request, *args, **kwargs)
  File "/Users/kei./Desktop/Django/wordbook/wordbook/views.py", line 156, in get
    list_for_its_loop.append(list_for_after_loop[n]['word_id'])
TypeError: 'int' object is not subscriptable
[15/Nov/2018 20:07:54] "GET /selvoc/wordbook/home/repeated_game/ HTTP/1.1" 500 103281
