Internal Server Error: /selvoc/wordbook/home/add_word
Traceback (most recent call last):
  File "/Users/kei./anaconda3/lib/python3.6/site-packages/django/core/handlers/exception.py", line 34, in inner
    response = get_response(request)
  File "/Users/kei./anaconda3/lib/python3.6/site-packages/django/core/handlers/base.py", line 126, in _get_response
    response = self.process_exception_by_middleware(e, request)
  File "/Users/kei./anaconda3/lib/python3.6/site-packages/django/core/handlers/base.py", line 124, in _get_response
    response = wrapped_callback(request, *callback_args, **callback_kwargs)
  File "/Users/kei./anaconda3/lib/python3.6/contextlib.py", line 52, in inner
    return func(*args, **kwds)
  File "/Users/kei./anaconda3/lib/python3.6/site-packages/django/views/generic/base.py", line 68, in view
    return self.dispatch(request, *args, **kwargs)
  File "/Users/kei./anaconda3/lib/python3.6/site-packages/django/contrib/auth/mixins.py", line 52, in dispatch
    return super().dispatch(request, *args, **kwargs)
  File "/Users/kei./anaconda3/lib/python3.6/site-packages/django/views/generic/base.py", line 88, in dispatch
    return handler(request, *args, **kwargs)
  File "/Users/kei./anaconda3/lib/python3.6/site-packages/django/views/generic/edit.py", line 133, in get
    return self.render_to_response(self.get_context_data())
  File "/Users/kei./anaconda3/lib/python3.6/site-packages/django/views/generic/edit.py", line 66, in get_context_data
    kwargs['form'] = self.get_form()
  File "/Users/kei./anaconda3/lib/python3.6/site-packages/django/views/generic/edit.py", line 33, in get_form
    return form_class(**self.get_form_kwargs())
  File "/Users/kei./Desktop/Django/wordbook/wordbook/forms.py", line 11, in __init__
    super(WordAddForm, self).__init__(*args, **kwargs)
TypeError: __init__() got an unexpected keyword argument 'user'
